<?xml version="1.0" encoding="utf-8"?>
<robot
  name="rm_65_description">

  <link name="base">
    <inertial>
      <origin xyz="0 0 0" rpy="0 0 0" />
      <mass value="0.0" />
      <inertia ixx="0.0" ixy="0.0" ixz="0.0" iyy="0.0" iyz="0.0" izz="0.0" />
    </inertial>
  </link>

  <joint
    name="base_joint"
    type="fixed">
    <origin
      xyz="0 0 0"
      rpy="0 0 0" />
    <parent
      link="base" />
    <child
      link="base_link" />
    <axis
      xyz="0 0 0" />
  </joint>
  
  <link name="base_link">
    <inertial>
      <origin xyz="0 0 0" rpy="0 0 0" />
      <mass value="0.0" />
      <inertia ixx="0.0" ixy="0.0" ixz="0.0" iyy="0.0" iyz="0.0" izz="0.0" />
    </inertial>
  </link>

  <joint
    name="robot_base_joint"
    type="fixed">
    <origin
      xyz="0 0 0"
      rpy="0 0 0" />
    <parent
      link="base_link" />
    <child
      link="robot_base_link" />
    <axis
      xyz="0 0 0" />
  </joint>

  <link
    name="robot_base_link">
    <inertial>
      <origin
        xyz="0.00043296 3.5291E-05 0.059942"
        rpy="0 0 0" />
      <mass
        value="0.84105" />
      <inertia
        ixx="0.0017261"
        ixy="2.5275E-06"
        ixz="3.6769E-05"
        iyy="0.0017099"
        iyz="-1.68E-06"
        izz="0.00090402" />
    </inertial>
    <visual>
      <origin
        xyz="0 0 0"
        rpy="0 0 0" />
      <geometry>
        <mesh
          filename="package://rm_description/meshes/singlearm/rm75_6f/base_link_l.STL" />
      </geometry>
      <material
        name="">
        <color
          rgba="1 1 1 1" />
      </material>
    </visual>
    <collision>
      <origin
        xyz="0 0 0"
        rpy="0 0 0" />
      <geometry>
        <mesh
          filename="package://rm_description/meshes/singlearm/rm75_6f/base_link_l.STL" />
      </geometry>
    </collision>
  </link>

  <link
    name="Link1">
    <inertial>
      <origin
        xyz="-2.1376E-07 0.025186 -0.021108"
        rpy="0 0 0" />
      <mass
        value="0.59356" />
      <inertia
        ixx="0.0012661"
        ixy="-9.8019E-09"
        ixz="-1.2951E-08"
        iyy="0.00056135"
        iyz="-0.00021122"
        izz="0.0011817" />
    </inertial>
    <visual>
      <origin
        xyz="0 0 0"
        rpy="0 0 0" />
      <geometry>
        <mesh
          filename="package://rm_description/meshes/singlearm/rm75_6f/link1_l.STL" />
      </geometry>
      <material
        name="">
        <color
          rgba="1 1 1 1" />
      </material>
    </visual>
    <collision>
      <origin
        xyz="0 0 0"
        rpy="0 0 0" />
      <geometry>
        <mesh
          filename="package://rm_description/meshes/singlearm/rm75_6f/link1_l.STL" />
      </geometry>
    </collision>
  </link>
  <joint
    name="joint1"
    type="revolute">
    <origin
      xyz="0 0 0.2405"
      rpy="-1.5708 0 0" />
    <parent
      link="robot_base_link" />
    <child
      link="Link1" />
    <axis
      xyz="0 -1 0" />
    <limit
      lower="-3.100"
      upper="3.100"
      effort="100"
      velocity="1" />
  </joint>
  <link
    name="Link2">
    <inertial>
      <origin
        xyz="4.1111E-07 0.011078 0.076129"
        rpy="0 0 0" />
      <mass
        value="0.43285" />
      <inertia
        ixx="0.0012584"
        ixy="5.6315E-09"
        ixz="1.3348E-09"
        iyy="0.0012225"
        iyz="0.000279"
        izz="0.00031747" />
    </inertial>
    <visual>
      <origin
        xyz="0 0 0"
        rpy="0 0 0" />
      <geometry>
        <mesh
          filename="package://rm_description/meshes/singlearm/rm75_6f/link2_l.STL" />
      </geometry>
      <material
        name="">
        <color
          rgba="1 1 1 1" />
      </material>
    </visual>
    <collision>
      <origin
        xyz="0 0 0"
        rpy="0 0 0" />
      <geometry>
        <mesh
          filename="package://rm_description/meshes/singlearm/rm75_6f/link2_l.STL" />
      </geometry>
    </collision>
  </link>
  <joint
    name="joint2"
    type="revolute">
    <origin
      xyz="0 0 0"
      rpy="1.5708 0 0" />
    <parent
      link="Link1" />
    <child
      link="Link2" />
    <axis
      xyz="0 1 0" />
    <limit
      lower="-2.263"
      upper="2.263"
      effort="100"
      velocity="1" />
  </joint>
  <link
    name="Link3">
    <inertial>
      <origin
        xyz="-4.7932E-07 0.027347 -0.023544"
        rpy="0 0 0" />
      <mass
        value="0.43132" />
      <inertia
        ixx="0.00079433"
        ixy="1.0334E-08"
        ixz="-2.329E-09"
        iyy="0.00031507"
        iyz="-0.00014262"
        izz="0.00073037" />
    </inertial>
    <visual>
      <origin
        xyz="0 0 0"
        rpy="0 0 0" />
      <geometry>
        <mesh
          filename="package://rm_description/meshes/singlearm/rm75_6f/link3_l.STL" />
      </geometry>
      <material
        name="">
        <color
          rgba="1 1 1 1" />
      </material>
    </visual>
    <collision>
      <origin
        xyz="0 0 0"
        rpy="0 0 0" />
      <geometry>
        <mesh
          filename="package://rm_description/meshes/singlearm/rm75_6f/link3_l.STL" />
      </geometry>
    </collision>
  </link>
  <joint
    name="joint3"
    type="revolute">
    <origin
      xyz="0 0 0.256"
      rpy="-1.5708 0 0" />
    <parent
      link="Link2" />
    <child
      link="Link3" />
    <axis
      xyz="0 -1 0" />
    <limit
      lower="-3.100"
      upper="3.100"
      effort="100"
      velocity="1" />
  </joint>
  <link
    name="Link4">
    <inertial>
      <origin
        xyz="5.0444E-06 0.010569 0.059593"
        rpy="0 0 0" />
      <mass
        value="0.28963" />
      <inertia
        ixx="0.00063737"
        ixy="-3.8666E-08"
        ixz="7.0522E-08"
        iyy="0.00061418"
        iyz="0.00014461"
        izz="0.00015648" />
    </inertial>
    <visual>
      <origin
        xyz="0 0 0"
        rpy="0 0 0" />
      <geometry>
        <mesh
          filename="package://rm_description/meshes/singlearm/rm75_6f/link4_l.STL" />
      </geometry>
      <material
        name="">
        <color
          rgba="1 1 1 1" />
      </material>
    </visual>
    <collision>
      <origin
        xyz="0 0 0"
        rpy="0 0 0" />
      <geometry>
        <mesh
          filename="package://rm_description/meshes/singlearm/rm75_6f/link4_l.STL" />
      </geometry>
    </collision>
  </link>
  <joint
    name="joint4"
    type="revolute">
    <origin
      xyz="0 0 0"
      rpy="1.5708 0 0" />
    <parent
      link="Link3" />
    <child
      link="Link4" />
    <axis
      xyz="0 1 0" />
    <limit
      lower="-2.350"
      upper="2.350"
      effort="100"
      velocity="1" />
  </joint>
  <link
    name="Link5">
    <inertial>
      <origin
        xyz="1.1466E-06 0.021541 -0.018041"
        rpy="0 0 0" />
      <mass
        value="0.23941" />
      <inertia
        ixx="0.00028594"
        ixy="1.8435E-09"
        ixz="2.6611E-09"
        iyy="0.00011989"
        iyz="-4.4238E-05"
        izz="0.00026273" />
    </inertial>
    <visual>
      <origin
        xyz="0 0 0"
        rpy="0 0 0" />
      <geometry>
        <mesh
          filename="package://rm_description/meshes/singlearm/rm75_6f/link5_l.STL" />
      </geometry>
      <material
        name="">
        <color
          rgba="1 1 1 1" />
      </material>
    </visual>
    <collision>
      <origin
        xyz="0 0 0"
        rpy="0 0 0" />
      <geometry>
        <mesh
          filename="package://rm_description/meshes/singlearm/rm75_6f/link5_l.STL" />
      </geometry>
    </collision>
  </link>
  <joint
    name="joint5"
    type="revolute">
    <origin
      xyz="0 0 0.21"
      rpy="-1.5708 0 0" />
    <parent
      link="Link4" />
    <child
      link="Link5" />
    <axis
      xyz="0 -1 0" />
    <limit
      lower="-3.100"
      upper="3.100"
      effort="100"
      velocity="1" />
  </joint>
  <link
    name="Link6">
    <inertial>
      <origin
        xyz="4.5754E-06 0.0073681 0.059382"
        rpy="0 0 0" />
      <mass
        value="0.21879" />
      <inertia
        ixx="0.00035053"
        ixy="-1.7437E-08"
        ixz="3.1653E-08"
        iyy="0.00033447"
        iyz="7.824E-05"
        izz="0.00010492" />
    </inertial>
    <visual>
      <origin
        xyz="0 0 0"
        rpy="0 0 0" />
      <geometry>
        <mesh
          filename="package://rm_description/meshes/singlearm/rm75_6f/link6_l.STL" />
      </geometry>
      <material
        name="">
        <color
          rgba="1 1 1 1" />
      </material>
    </visual>
    <collision>
      <origin
        xyz="0 0 0"
        rpy="0 0 0" />
      <geometry>
        <mesh
          filename="package://rm_description/meshes/singlearm/rm75_6f/link6_l.STL" />
      </geometry>
    </collision>
  </link>
  <joint
    name="joint6"
    type="revolute">
    <origin
      xyz="0 0 0"
      rpy="1.5708 0 0" />
    <parent
      link="Link5" />
    <child
      link="Link6" />
    <axis
      xyz="0 1 0" />
    <limit
      lower="-2.230"
      upper="2.230"
      effort="100"
      velocity="1" />
  </joint>
  <link
    name="Link7">
    <inertial>
      <origin
        xyz="0.00032231 -0.0001782 -0.028676"
        rpy="0 0 0" />
      <mass
        value="0.14433" />
      <inertia
        ixx="3.6119E-05"
        ixy="-1.3242E-06"
        ixz="-3.2733E-08"
        iyy="3.4626E-05"
        iyz="7.6694E-09"
        izz="6.1463E-05" />
    </inertial>
    <visual>
      <origin
        xyz="0 0 0"
        rpy="0 0 0" />
      <geometry>
        <mesh
          filename="package://rm_description/meshes/singlearm/rm75_6f/link7_l.STL" />
      </geometry>
      <material
        name="">
        <color
          rgba="1 1 1 1" />
      </material>
    </visual>
    <collision>
      <origin
        xyz="0 0 0"
        rpy="0 0 0" />
      <geometry>
        <mesh
          filename="package://rm_description/meshes/singlearm/rm75_6f/link7_l.STL" />
      </geometry>
    </collision>
  </link>
  <joint
    name="joint7"
    type="revolute">
    <origin
      xyz="0 0 0.1725"
      rpy="0 0 0" />
    <parent
      link="Link6" />
    <child
      link="Link7" />
    <axis
      xyz="0 0 1" />
    <limit
      lower="-6.280"
      upper="6.280"
      effort="100"
      velocity="1" />
  </joint>
  

  <link name="arm_end_link">
    <inertial>
      <origin xyz="0 0 0" rpy="0 0 0" />
      <mass value="0.0" />
      <inertia ixx="0.0" ixy="0.0" ixz="0.0" iyy="0.0" iyz="0.0" izz="0.0" />
    </inertial>
  </link>
  <joint
    name="arm_endjoint"
    type="fixed">
    <origin
      xyz="0 0 0 "
      rpy="0 0 0 " />
    <parent
      link="Link7" />
    <child
      link="arm_end_link" />
    <axis
      xyz="0 0 0" />
  </joint>

  <link
    name="L_hand_base_link">
    <inertial>
      <origin
        xyz="-6.24288400908994E-05 0.00368445021108559 -0.0826064863965231"
        rpy="0 0 0" />
      <mass
        value="0.259445165128865" />
      <inertia
        ixx="0.00022365344025756"
        ixy="-1.13436481934473E-06"
        ixz="5.34161934445467E-07"
        iyy="0.00026679338415638"
        iyz="1.40944118648866E-05"
        izz="0.000132846630274859" />
    </inertial>
    <visual>
      <origin
        xyz="0 0 0"
        rpy="0 0 0" />
      <geometry>
        <mesh
          filename="package://rm_description/meshes/singlearm/inspire_hand/l_base_link.STL" />
      </geometry>
      <material
        name="">
        <color
          rgba="1 1 1 1" />
      </material>
    </visual>
    <collision>
      <origin
        xyz="0 0 0"
        rpy="0 0 0" />
      <geometry>
        <mesh
          filename="package://rm_description/meshes/singlearm/inspire_hand/l_base_link.STL" />
      </geometry>
    </collision>
  </link>

  <link
    name="left_thumb_swing">
    <inertial>
      <origin
        xyz="-0.00184772613419589 -0.000437179099690016 0.00313589310434411"
        rpy="0 0 0" />
      <mass
        value="0.00115518743162309" />
      <inertia
        ixx="6.14919569328236E-08"
        ixy="5.60732910597656E-09"
        ixz="-3.41066835700806E-09"
        iyy="3.91193865762758E-08"
        iyz="-8.06984149203055E-10"
        izz="6.18161684388652E-08" />
    </inertial>
    <visual>
      <origin
        xyz="0 0 0"
        rpy="0 0 0" />
      <geometry>
        <mesh
          filename="package://rm_description/meshes/singlearm/inspire_hand/left_thumb_swing.STL" />
      </geometry>
      <material
        name="">
        <color
          rgba="1 1 1 1" />
      </material>
    </visual>
    <collision>
      <origin
        xyz="0 0 0"
        rpy="0 0 0" />
      <geometry>
        <mesh
          filename="package://rm_description/meshes/singlearm/inspire_hand/left_thumb_swing.STL" />
      </geometry>
    </collision>
  </link>
  <joint
    name="left_thumb_swing_joint"
    type="revolute">
    <origin
      xyz="0.0269 -0.02101 -0.07075"
      rpy="-3.1416 0 -3.1416" />
    <parent
      link="L_hand_base_link" />
    <child
      link="left_thumb_swing" />
    <axis
      xyz="0 0 1" />
    <limit
      lower="0"
      upper="1.7"
      effort="1"
      velocity="100" />
  </joint>
  <link
    name="left_thumb_1">
    <inertial>
      <origin
        xyz="-0.0167591242737366 0.00921112383501533 -0.00940298171557882"
        rpy="0 0 0" />
      <mass
        value="0.03" />
      <inertia
        ixx="1.04464326592721E-06"
        ixy="8.43518653247496E-08"
        ixz="4.30246542461423E-10"
        iyy="1.13248311287668E-06"
        iyz="-3.2733269008621E-10"
        izz="1.4363514294434E-06" />
    </inertial>
    <visual>
      <origin
        xyz="0 0 0"
        rpy="0 0 0" />
      <geometry>
        <mesh
          filename="package://rm_description/meshes/singlearm/inspire_hand/left_thumb_1.STL" />
      </geometry>
      <material
        name="">
        <color
          rgba="1 1 1 1" />
      </material>
    </visual>
    <collision>
      <origin
        xyz="0 0 0"
        rpy="0 0 0" />
      <geometry>
        <mesh
          filename="package://rm_description/meshes/singlearm/inspire_hand/left_thumb_1.STL" />
      </geometry>
    </collision>
  </link>
  <joint
    name="left_thumb_1_joint"
    type="revolute">
    <origin
      xyz="-0.007567 -0.01145 0.00125"
      rpy="1.5708 0 0.23233" />
    <parent
      link="left_thumb_swing" />
    <child
      link="left_thumb_1" />
    <axis
      xyz="0.19357 0 -0.98109" />
    <limit
      lower="0.04"
      upper="0.92"
      effort="1"
      velocity="100" />
  </joint>
  <link
    name="left_thumb_2">
    <inertial>
      <origin
        xyz="-0.0101809417296302 0.00225977029721441 -0.00854142548261862"
        rpy="0 0 0" />
      <mass
        value="0.02" />
      <inertia
        ixx="4.56062152110622E-07"
        ixy="6.18635738534935E-08"
        ixz="5.54386686828183E-11"
        iyy="4.26592488515216E-07"
        iyz="-2.17032482396712E-10"
        izz="4.38692962619055E-07" />
    </inertial>
    <visual>
      <origin
        xyz="0 0 0"
        rpy="0 0 0" />
      <geometry>
        <mesh
          filename="package://rm_description/meshes/singlearm/inspire_hand/left_thumb_2.STL" />
      </geometry>
      <material
        name="">
        <color
          rgba="1 1 1 1" />
      </material>
    </visual>
    <collision>
      <origin
        xyz="0 0 0"
        rpy="0 0 0" />
      <geometry>
        <mesh
          filename="package://rm_description/meshes/singlearm/inspire_hand/left_thumb_2.STL" />
      </geometry>
    </collision>
  </link>
  <joint
    name="left_thumb_2_joint"
    type="revolute">
    <origin
      xyz="-0.039173 0.011958 -0.00085"
      rpy="0 0 0" />
    <parent
      link="left_thumb_1" />
    <child
      link="left_thumb_2" />
    <axis
      xyz="0.19357 0 -0.98109" />
    <limit
      lower="0"
      upper="3.14"
      effort="1"
      velocity="100" />
    <mimic
        joint="left_thumb_1_joint"
        multiplier="0.40"
        offset="0" />
  </joint>
  <link
    name="left_thumb_3">
    <inertial>
      <origin
        xyz="-0.0168088610672642 0.00363291504796805 -0.00874331200533507"
        rpy="0 0 0" />
      <mass
        value="0.014" />
      <inertia
        ixx="5.64414545344182E-07"
        ixy="2.2463040972391E-07"
        ixz="-9.68542531793602E-10"
        iyy="8.42890432911496E-07"
        iyz="5.71733921923626E-10"
        izz="9.25701490946238E-07" />
    </inertial>
    <visual>
      <origin
        xyz="0 0 0"
        rpy="0 0 0" />
      <geometry>
        <mesh
          filename="package://rm_description/meshes/singlearm/inspire_hand/left_thumb_3.STL" />
      </geometry>
      <material
        name="">
        <color
          rgba="1 1 1 1" />
      </material>
    </visual>
    <collision>
      <origin
        xyz="0 0 0"
        rpy="0 0 0" />
      <geometry>
        <mesh
          filename="package://rm_description/meshes/singlearm/inspire_hand/left_thumb_3.STL" />
      </geometry>
    </collision>
  </link>
  <joint
    name="left_thumb_3_joint"
    type="revolute">
    <origin
      xyz="-0.020827 0.0074327 0.0002"
      rpy="0 0 0" />
    <parent
      link="left_thumb_2" />
    <child
      link="left_thumb_3" />
    <axis
      xyz="0.19357 0 -0.98109" />
    <limit
      lower="0"
      upper="3.14"
      effort="1"
      velocity="100" />
    <mimic
        joint="left_thumb_1_joint"
        multiplier="0.60"
        offset="0" />
  </joint>
  <link
    name="left_index_1">
    <inertial>
      <origin
        xyz="0.00284971838882705 0.0121606900201158 -0.00779932656701256"
        rpy="0 0 0" />
      <mass
        value="0.00719948017029058" />
      <inertia
        ixx="1.27186018148011E-06"
        ixy="-9.9574434089598E-08"
        ixz="5.32989867607526E-12"
        iyy="5.91193769989315E-07"
        iyz="8.56656303683012E-11"
        izz="1.32912624828403E-06" />
    </inertial>
    <visual>
      <origin
        xyz="0 0 0"
        rpy="0 0 0" />
      <geometry>
        <mesh
          filename="package://rm_description/meshes/singlearm/inspire_hand/left_index_1.STL" />
      </geometry>
      <material
        name="">
        <color
          rgba="1 1 1 1" />
      </material>
    </visual>
    <collision>
      <origin
        xyz="0 0 0"
        rpy="0 0 0" />
      <geometry>
        <mesh
          filename="package://rm_description/meshes/singlearm/inspire_hand/left_index_1.STL" />
      </geometry>
    </collision>
  </link>
  <joint
    name="left_index_1_joint"
    type="revolute">
    <origin
      xyz="0.039829 -0.00056467 -0.15636"
      rpy="-1.5359 0 -1.5708" />
    <parent
      link="L_hand_base_link" />
    <child
      link="left_index_1" />
    <axis
      xyz="0 0 -1" />
    <limit
      lower="0"
      upper="1.6"
      effort="1"
      velocity="100" />
  </joint>
  <link
    name="left_index_2">
    <inertial>
      <origin
        xyz="-0.00158837869328786 0.0256544689953271 -0.00749252483164686"
        rpy="0 0 0" />
      <mass
        value="0.00968686999051252" />
      <inertia
        ixx="2.28950934688236E-06"
        ixy="-3.23784715854037E-07"
        ixz="2.59557220847794E-10"
        iyy="3.57396661758505E-07"
        iyz="2.7798873971777E-09"
        izz="2.3024700664577E-06" />
    </inertial>
    <visual>
      <origin
        xyz="0 0 0"
        rpy="0 0 0" />
      <geometry>
        <mesh
          filename="package://rm_description/meshes/singlearm/inspire_hand/left_index_2.STL" />
      </geometry>
      <material
        name="">
        <color
          rgba="1 1 1 1" />
      </material>
    </visual>
    <collision>
      <origin
        xyz="0 0 0"
        rpy="0 0 0" />
      <geometry>
        <mesh
          filename="package://rm_description/meshes/singlearm/inspire_hand/left_index_2.STL" />
      </geometry>
    </collision>
  </link>
  <joint
    name="left_index_2_joint"
    type="revolute">
    <origin
      xyz="0.0043282 0.032488 -0.0003"
      rpy="0 0 0" />
    <parent
      link="left_index_1" />
    <child
      link="left_index_2" />
    <axis
      xyz="0 0 -1" />
    <limit
      lower="0"
      upper="3.14"
      effort="1"
      velocity="100" />
    <mimic
        joint="left_index_1_joint"
        multiplier="1.05"
        offset="0" />
  </joint>
  <link
    name="left_middle_1">
    <inertial>
      <origin
        xyz="0.00229271394242235 0.0122778605414752 -0.00779931823074317"
        rpy="0 0 0" />
      <mass
        value="0.00719950322487974" />
      <inertia
        ixx="1.27951858905779E-06"
        ixy="-6.81813021711598E-08"
        ixz="1.58551121588184E-12"
        iyy="5.83543537428453E-07"
        iyz="8.56179612611608E-11"
        izz="1.32913234511164E-06" />
    </inertial>
    <visual>
      <origin
        xyz="0 0 0"
        rpy="0 0 0" />
      <geometry>
        <mesh
          filename="package://rm_description/meshes/singlearm/inspire_hand/left_middle_1.STL" />
      </geometry>
      <material
        name="">
        <color
          rgba="1 1 1 1" />
      </material>
    </visual>
    <collision>
      <origin
        xyz="0 0 0"
        rpy="0 0 0" />
      <geometry>
        <mesh
          filename="package://rm_description/meshes/singlearm/inspire_hand/left_middle_1.STL" />
      </geometry>
    </collision>
  </link>
  <joint
    name="left_middle_1_joint"
    type="revolute">
    <origin
      xyz="0.01825 -0.00056467 -0.157"
      rpy="-1.5708 0 -1.5708" />
    <parent
      link="L_hand_base_link" />
    <child
      link="left_middle_1" />
    <axis
      xyz="0 0 -1" />
    <limit
      lower="0"
      upper="1.6"
      effort="1"
      velocity="100" />
  </joint>
  <link
    name="left_middle_2">
    <inertial>
      <origin
        xyz="-7.51983994427274E-05 0.027448753770842 -0.00750059894166984"
        rpy="0 0 0" />
      <mass
        value="0.0104611931926301" />
      <inertia
        ixx="2.75831931773332E-06"
        ixy="-4.66412841401028E-07"
        ixz="7.3576656177528E-12"
        iyy="4.22466538741155E-07"
        iyz="1.79608426686179E-11"
        izz="2.80722617348706E-06" />
    </inertial>
    <visual>
      <origin
        xyz="0 0 0"
        rpy="0 0 0" />
      <geometry>
        <mesh
          filename="package://rm_description/meshes/singlearm/inspire_hand/left_middle_2.STL" />
      </geometry>
      <material
        name="">
        <color
          rgba="1 1 1 1" />
      </material>
    </visual>
    <collision>
      <origin
        xyz="0 0 0"
        rpy="0 0 0" />
      <geometry>
        <mesh
          filename="package://rm_description/meshes/singlearm/inspire_hand/left_middle_2.STL" />
      </geometry>
    </collision>
  </link>
  <joint
    name="left_middle_2_joint"
    type="revolute">
    <origin
      xyz="0.0028436 0.032651 -0.0003"
      rpy="0 0 0" />
    <parent
      link="left_middle_1" />
    <child
      link="left_middle_2" />
    <axis
      xyz="0 0 -1" />
    <limit
      lower="0"
      upper="3.14"
      effort="1"
      velocity="100" />
    <mimic
        joint="left_middle_1_joint"
        multiplier="1.05"
        offset="0" />
  </joint>
  <link
    name="left_ring_1">
    <inertial>
      <origin
        xyz="0.00240530428455067 0.0122563079467745 -0.00779931923444504"
        rpy="0 0 0" />
      <mass
        value="0.00719949770218712" />
      <inertia
        ixx="1.27820682409824E-06"
        ixy="-7.45572429780095E-08"
        ixz="2.25718181815559E-12"
        iyy="5.84853511073517E-07"
        iyz="8.56222330413956E-11"
        izz="1.32913088941838E-06" />
    </inertial>
    <visual>
      <origin
        xyz="0 0 0"
        rpy="0 0 0" />
      <geometry>
        <mesh
          filename="package://rm_description/meshes/singlearm/inspire_hand/left_ring_1.STL" />
      </geometry>
      <material
        name="">
        <color
          rgba="1 1 1 1" />
      </material>
    </visual>
    <collision>
      <origin
        xyz="0 0 0"
        rpy="0 0 0" />
      <geometry>
        <mesh
          filename="package://rm_description/meshes/singlearm/inspire_hand/left_ring_1.STL" />
      </geometry>
    </collision>
  </link>
  <joint
    name="left_ring_1_joint"
    type="revolute">
    <origin
      xyz="-0.0033817 -0.00056467 -0.15689"
      rpy="-1.6232 0 -1.5708" />
    <parent
      link="L_hand_base_link" />
    <child
      link="left_ring_1" />
    <axis
      xyz="0 0 -1" />
    <limit
      lower="0"
      upper="1.6"
      effort="1"
      velocity="100" />
  </joint>
  <link
    name="left_ring_2">
    <inertial>
      <origin
        xyz="-0.000667145407605998 0.0256949163202511 -0.00749252997688842"
        rpy="0 0 0" />
      <mass
        value="0.00968685177133057" />
      <inertia
        ixx="2.26381138740299E-06"
        ixy="-3.92210300202205E-07"
        ixz="3.58404653503589E-10"
        iyy="3.83095000534084E-07"
        iyz="2.77027363965472E-09"
        izz="2.30247104599333E-06" />
    </inertial>
    <visual>
      <origin
        xyz="0 0 0"
        rpy="0 0 0" />
      <geometry>
        <mesh
          filename="package://rm_description/meshes/singlearm/inspire_hand/left_ring_2.STL" />
      </geometry>
      <material
        name="">
        <color
          rgba="1 1 1 1" />
      </material>
    </visual>
    <collision>
      <origin
        xyz="0 0 0"
        rpy="0 0 0" />
      <geometry>
        <mesh
          filename="package://rm_description/meshes/singlearm/inspire_hand/left_ring_2.STL" />
      </geometry>
    </collision>
  </link>
  <joint
    name="left_ring_2_joint"
    type="revolute">
    <origin
      xyz="0.0031431 0.032624 -0.0003"
      rpy="0 0 0" />
    <parent
      link="left_ring_1" />
    <child
      link="left_ring_2" />
    <axis
      xyz="0 0 -1" />
    <limit
      lower="0"
      upper="3.14"
      effort="1"
      velocity="100" />
    <mimic
        joint="left_ring_1_joint"
        multiplier="1.05"
        offset="0" />
  </joint>
  <link
    name="left_little_1">
    <inertial>
      <origin
        xyz="0.00233010474276744 0.0122708215539047 -0.00779931620909799"
        rpy="0 0 0" />
      <mass
        value="0.00719949925435212" />
      <inertia
        ixx="1.27909590457063E-06"
        ixy="-7.02999032363559E-08"
        ixz="1.57057552160854E-12"
        iyy="5.83965373542566E-07"
        iyz="8.55933667502959E-11"
        izz="1.32913130646923E-06" />
    </inertial>
    <visual>
      <origin
        xyz="0 0 0"
        rpy="0 0 0" />
      <geometry>
        <mesh
          filename="package://rm_description/meshes/singlearm/inspire_hand/left_little_1.STL" />
      </geometry>
      <material
        name="">
        <color
          rgba="1 1 1 1" />
      </material>
    </visual>
    <collision>
      <origin
        xyz="0 0 0"
        rpy="0 0 0" />
      <geometry>
        <mesh
          filename="package://rm_description/meshes/singlearm/inspire_hand/left_little_1.STL" />
      </geometry>
    </collision>
  </link>
  <joint
    name="left_little_1_joint"
    type="revolute">
    <origin
      xyz="-0.024772 -0.00056467 -0.15377"
      rpy="-1.6755 0 -1.5708" />
    <parent
      link="L_hand_base_link" />
    <child
      link="left_little_1" />
    <axis
      xyz="0 0 -1" />
    <limit
      lower="0"
      upper="1.6"
      effort="1"
      velocity="100" />
  </joint>
  <link
    name="left_little_2">
    <inertial>
      <origin
        xyz="-0.00241293669173222 0.0208349583856417 -0.00750030972388035"
        rpy="0 0 0" />
      <mass
        value="0.00759258702894185" />
      <inertia
        ixx="1.24797764618213E-06"
        ixy="-1.85441230726232E-07"
        ixz="2.6668802312491E-12"
        iyy="2.60164254907827E-07"
        iyz="1.28065987445323E-11"
        izz="1.23906779005459E-06" />
    </inertial>
    <visual>
      <origin
        xyz="0 0 0"
        rpy="0 0 0" />
      <geometry>
        <mesh
          filename="package://rm_description/meshes/singlearm/inspire_hand/left_little_2.STL" />
      </geometry>
      <material
        name="">
        <color
          rgba="1 1 1 1" />
      </material>
    </visual>
    <collision>
      <origin
        xyz="0 0 0"
        rpy="0 0 0" />
      <geometry>
        <mesh
          filename="package://rm_description/meshes/singlearm/inspire_hand/left_little_2.STL" />
      </geometry>
    </collision>
  </link>
  <joint
    name="left_little_2_joint"
    type="revolute">
    <origin
      xyz="0.002943 0.032643 -0.0003"
      rpy="0 0 0" />
    <parent
      link="left_little_1" />
    <child
      link="left_little_2" />
    <axis
      xyz="0 0 -1" />
    <limit
      lower="0"
      upper="3.14"
      effort="1"
      velocity="100" />
    <mimic
        joint="left_little_1_joint"
        multiplier="1.05"
        offset="0" />
  </joint>

  <joint
    name="arm_to_hand_virtual"
    type="fixed">
    <origin
      xyz="0 0 0.01"
      rpy="0 3.1416 -1.5708" />
    <parent
      link="Link7" />
    <child
      link="L_hand_base_link" />
    <axis
      xyz="0 0 0" />
  </joint>
  
  <link name="L_hand_endeffector">
    <inertial>
      <origin xyz="0 0 0" rpy="0 0 0" />
      <mass value="0.0" />
      <inertia ixx="0.0" ixy="0.0" ixz="0.0" iyy="0.0" iyz="0.0" izz="0.0" />
    </inertial>
  </link>

  <joint
    name="L_hand_joint_endeffector"
    type="fixed">
    <origin
      xyz="0.020 -0.051 -0.156"
      rpy="2.222 0 0.05" />
    <parent
      link="L_hand_base_link" />
    <child
      link="L_hand_endeffector" />
    <axis
      xyz="0 0 0" />
  </joint>
      <!-- xyz="0.018 0.051 0.156"
      rpy="2.74 0 0.05" -->
</robot>
